Workbook
Name ACTION: #REF!

Sheet Guideline
A1: Guideline to make and understand Unit Test Case
A3: 1. Overview
A4: - In the template, Unit test cases are based on functions. Each sheet presents test cases for one function.
A5: - Cover: General information of the project and Unit Test cases
A6: - FunctionList: The list of Classes and Functions in the document. + To control that the number of Unit TC meets customer's requirement or the norm, user should fill value for 'Normal number of Test cases/KLOC'.
A7: + Click on Function link to open the related Test cases of the function. Note: You should create new Function sheet before creating the link
A8: - Test Report: provive the overview results of Functions Unit test: Test coverage, Test successful coverage (Summary, for normal/abnormal/boundary cases)
A9: Note: Should check the formula of "Sub Total" if you add more functions
A11: 2. Content in Test function sheet
A12: 2.1 Combination of test cases.
A13: - To verify that number of Unit TC meets customer's requirement or not. User has to fill number LOC of tested function and fill value of 'Normal number test cases/KLOC' item in FunctionList sheet, which is required by customer or normal value. The number of lacked TC is shown in 'Lack of test cases' item.
A14: - If the number of Unit TC does not meet the requirement, creator should explain the reasons.
... A47: - Test requirement: Brief description about requirements which are tested in this function, it is not mandatory.

Sheet Cover
B2: UNIT TEST DOCUMENT
A4: Project Name | B4: Woodwork Design, Crafting & Repair Booking Platform | E4: Creator | F4: Group GSP48
A5: Project Code | B5: SP25SE026 | E5: Issue Date | F5: 45779
A6: Document Code | B6: =B5&"_"&"UnitTestReport"&"_"&"vx.x" -> SP25SE026_UnitTestReport_vx.x | E6: Version | F6: 1
A9: Record of change
A10: Effective Date | B10: Version | C10: Change Item | D10: *A,D,M | E10: Change description | F10: Reference
A11: 45779 | B11: 1 | D11: A | E11: Init document
A12: 45779 | B12: 1 | D12: A | E12: Add registerWoodworker, createWalletOrderPayment, createUserAddress function
A13: 45779 | B13: 1 | D13: A | E13: Add signup, saveQuotatationDetails, saveGuaranteeQuoationDetails functions
A14: 45779 | B14: 1 | D14: A | E14: Add createPost, createContractCustomize, createReview function
A15: 45779 | B15: 1 | D15: A | E15: Add addDesignIdea, createPersonalOrder, createCustomizeOrder function

Sheet Functions
E2: Function List
A4: Project Name | E4: =Cover!B4 -> Woodwork Design, Crafting & Repair Booking Platform
A5: Project Code | E5: =Cover!B5 -> SP25SE026
A6: Normal number of Test cases/KLOC | E6: 100
A7: Test Environment Setup Description | E7: 1. Server 2. Database
A10: No | B10: Requirement Name | C10: Class Name | D10: Function Name | E10: Function Code(Optional) | F10: Sheet Name | G10: Description | H10: Pre-Condition
A11: 1 | C11: WoodworkerProfileController | D11: registerWoodworker | F11: =registerWoodworker!L2 -> registerWoodworker
A12: 2 | C12: WalletController | D12: createWalletOrderPayment | F12: =createWalletOrderPayment!L2 -> createWalletOrderPayment
A13: 3 | C13: UserAddressController | D13: createUserAddress | F13: =createUserAddress!L2 -> createUserAddress
A14: 4 | C14: AuthController | D14: signup | F14: signup
A15: 5 | C15: QuotationController | D15: saveQuotationDetails | F15: =saveQuotationDetails!L2 -> saveQuotationDetails
A16: 6 | C16: QuotationController | D16: saveGuaranteeQuotationDetails | F16: =saveGuaranteeQuotationDetails!L2 -> saveGuaranteeQuotationDetails
A17: 7 | C17: PostController | D17: createPost | F17: createPost!
A18: 8 | C18: ContractController | D18: createContractCustomize | F18: createContractCustomize!
A19: 9 | C19: ReviewController | D19: createReview | F19: =createReview!L2 -> createReview
A20: 10 | C20: DesignIdeaController | D20: addDesignIdea | F20: =addDesignIdea!L2 -> addDesignIdea
A21: 11 | C21: ServiceOrderController | D21: createPersonalOrder | F21: =createPersonalOrder!L2 -> createPersonalOrder
A22: 12 | C22: ServiceOrderController | D22: createCustomizeOrder | F22: =createCustomizeOrder!L2 -> createCustomizeOrder

Sheet Statistics
A2: UNIT TEST REPORT
A4: Project Name | B4: =Cover!B4 -> Woodwork Design, Crafting & Repair Booking Platform | D4: Creator
A5: Project Code | B5: =Cover!B5 -> SP25SE026 | D5: Reviewer/Approver
A6: Document Code | B6: =B5&"_"&"Test Report"&"_"&"vx.x" -> SP25SE026_Test Report_vx.x | D6: Issue Date | F6: 45778
A7: Notes
A11: No | B11: Function code | C11: Passed | D11: Failed | E11: Untested | F11: N | G11: A | H11: B | I11: Total Test Cases
A12: 1 | B12: registerWoodworker | C12: =registerWoodworker!A7 -> 11 | D12: =registerWoodworker!C7 -> 3 | E12: =registerWoodworker!F7 -> 0 | F12: =registerWoodworker!L7 -> 10 | G12: =registerWoodworker!M7 -> 3 | H12: =registerWoodworker!N8 -> 0 | I12: =registerWoodworker!O7 -> 14
A13: 2 | B13: createWalletOrderPayment | C13: =createWalletOrderPayment!A8 -> 7 | D13: =createWalletOrderPayment!C8 -> 0 | E13: =createWalletOrderPayment!F8 -> 0 | F13: =createWalletOrderPayment!L8 -> 5 | G13: =createWalletOrderPayment!M8 -> 1 | H13: =createWalletOrderPayment!N8 -> 1 | I13: =createWalletOrderPayment!O8 -> 7
A14: 3 | B14: createUserAddress | C14: =createUserAddress!A7 -> 5 | D14: =createUserAddress!C7 -> 1 | E14: =createUserAddress!F7 -> 0 | F14: =createUserAddress!L7 -> 5 | G14: =createUserAddress!M7 -> 0 | H14: =createUserAddress!N8 -> 0 | I14: =createUserAddress!O7 -> 6
A15: 4 | B15: signup | C15: =signup!A7 -> 12 | D15: =signup!C7 -> 2 | E15: =signup!F7 -> 1 | F15: =signup!L7 -> 11 | G15: =signup!M7 -> 3 | H15: =signup!N8 -> 0 | I15: =signup!G7 -> 0
A16: 5 | B16: saveQuotationDetails | C16: =saveQuotationDetails!A7 -> 11 | D16: =saveQuotationDetails!B7 -> 0 | E16: =saveQuotationDetails!C7 -> 3 | F16: =saveQuotationDetails!L7 -> 11 | G16: =saveQuotationDetails!M7 -> 3 | H16: =saveQuotationDetails!N8 -> 0 | I16: =saveQuotationDetails!G7 -> 0
A17: 6 | B17: saveGuaranteeQuotationDetails | C17: =saveGuaranteeQuotationDetails!A7 -> 12 | D17: =saveGuaranteeQuotationDetails!B7 -> 0 | E17: =saveGuaranteeQuotationDetails!F7 -> 1 | F17: =saveGuaranteeQuotationDetails!L7 -> 11 | G17: =saveGuaranteeQuotationDetails!M7 -> 3 | H17: =saveGuaranteeQuotationDetails!N8 -> 0 | I17: =saveGuaranteeQuotationDetails!G7 -> 0
A18: 7 | B18: createPost | C18: =createPost!A7 -> 8 | D18: =createPost!B7 -> 0 | E18: =createPost!F7 -> 0 | F18: =createPost!L7 -> 2 | G18: =createPost!M7 -> 5 | H18: =createPost!N8 -> 0 | I18: =createPost!G7 -> 0
A19: 8 | B19: createContractCustomize | C19: =createContractCustomize!A7 -> 12 | D19: =createContractCustomize!B7 -> 0 | E19: =createContractCustomize!C7 -> 2 | F19: =createContractCustomize!L7 -> 11 | G19: =createContractCustomize!M7 -> 3 | H19: =createContractCustomize!N8 -> 0 | I19: =createContractCustomize!G7 -> 0
A20: 9 | B20: createReview | C20: =createReview!A7 -> 12 | D20: =createReview!B7 -> 0 | E20: =createReview!F7 -> 1 | F20: =createReview!L7 -> 11 | G20: =createReview!M7 -> 3 | H20: =createReview!N8 -> 0 | I20: =createReview!G7 -> 0
A21: 10 | B21: addDesignIdea | C21: =addDesignIdea!A7 -> 8 | D21: =addDesignIdea!C7 -> 0 | E21: =addDesignIdea!F7 -> 0 | F21: =addDesignIdea!L7 -> 1 | G21: =addDesignIdea!M7 -> 7 | H21: =addDesignIdea!N8 -> 0 | I21: =addDesignIdea!O7 -> 8
A22: 11 | B22: createPersonalOrder | C22: =createPersonalOrder!A7 -> 8 | D22: =createPersonalOrder!C7 -> 2 | E22: =createPersonalOrder!F7 -> 0 | F22: =createPersonalOrder!L7 -> 1 | G22: =createPersonalOrder!M7 -> 9 | H22: =createPersonalOrder!N8 -> 0 | I22: =createPersonalOrder!O7 -> 10
A23: 12 | B23: createCustomizeOrder | C23: =createCustomizeOrder!A7 -> 9 | D23: =createCustomizeOrder!C7 -> 1 | E23: =createCustomizeOrder!F7 -> 0 | F23: =createCustomizeOrder!L7 -> 1 | G23: =createCustomizeOrder!M7 -> 9 | H23: =createCustomizeOrder!N8 -> 0 | I23: =createCustomizeOrder!O7 -> 10
B24: Sub total | C24: =SUM(C10:C23) -> 115 | D24: =SUM(D10:D23) -> 9 | E24: =SUM(E10:E23) -> 8 | F24: =SUM(F10:F23) -> 80 | G24: =SUM(G10:G23) -> 49 | H24: =SUM(H10:H23) -> 1 | I24: =SUM(I10:I23) -> 55
B26: Test coverage | D26: =(C24+D24)*100/(I24) -> 225.45455 | E26: %
B27: Test successful coverage | D27: =C24*100/(I24) -> 209.09091 | E27: %
B28: Normal case | D28: =F24*100/I24 -> 145.45455 | E28: %
B29: Abnormal case | D29: =G24*100/I24 -> 89.090909 | E29: %
B30: Boundary case | D30: =H24*100/I24 -> 1.8181818 | E30: %

Sheet Template
A2: Function Code | C2: =Functions!E11 -> 0 | F2: Function Name | L2: =Functions!D11 -> registerWoodworker
A3: Created By | C3: <Developer Name> | F3: Executed By
A4: Lines of code | C4: 100 | F4: Lack of test cases | L4: =IF(Functions!E6<>"N/A",SUM(C4*Functions!E6/1000,- O7),"N/A") -> -5
A5: Test requirement | C5: <Brief description about requirements which are tested in this function>
A6: Passed | C6: Failed | F6: Untested | L6: N/A/B | O6: Total Test Cases
A7: =COUNTIF(F47:HQ47,"P") -> 0 | C7: =COUNTIF(F47:HQ47,"F") -> 0 | F7: =SUM(O7,- A7,- C7) -> 15 | L7: =COUNTIF(E46:HQ46,"N") -> 0 | M7: =COUNTIF(E46:HQ46,"A") -> 0 | N7: =COUNTIF(E46:HQ46,"B") -> 0 | O7: =COUNTA(E9:HT9) -> 15
F9: UTCID01 | G9: UTCID02 | H9: UTCID02 | I9: UTCID02 | J9: UTCID02 | K9: UTCID02 | L9: UTCID07 | M9: UTCID08 | N9: UTCID09 | O9: UTCID10 | P9: UTCID11 | Q9: UTCID12 | R9: UTCID13 | S9: UTCID14 | T9: UTCID15
A10: Condition | B10: Precondition
B14: a
D15: -2 | F15: O
D16: -1 | L16: O
D17: 0 | G17: O | H17: O | I17: O
D18: 1 | J18: O | K18: O
B19: b
D20: 0 | G20: O | H20: O
D21: -2 | J21: O | K21: O | L21: O
D22: 2 | I22: O
B23: c
D24: 0 | G24: O
D25: 1 | H25: O | I25: O | J25: O
D26: 3 | L26: O
D27: 5 | K27: O
A33: Confirm | B33: Return
B34: list
D35: null | F35: O | H35: O | K35: O
D36: size = 0 | G36: O
D37: {-1/2} | I37: O
D38: {1,1} | J38: O
D39: {1,-3} | L39: O
B40: Exception
B42: Log message
D43: "please input a>= -1" | F43: O
A45: Result | B45: Type(N : Normal, A : Abnormal, B : Boundary) | F45: A | G45: N | H45: N | I45: N | J45: N | K45: N | L45: B
B46: Passed/Failed
B47: Executed Date | F47: 39139 | G47: 39139 | H47: 39139 | I47: 39139 | J47: 39139 | K47: 39139 | L47: 39144
B48: Defect ID

Sheet registerWoodworker
A2: Function Code | F2: Function Name | L2: =Functions!D11 -> registerWoodworker
A3: Created By | C3: An | F3: Executed By | L3: An
A4: Lines of code | C4: 100 | F4: Lack of test cases | L4: =IF(Functions!E6<>"N/A",SUM(C4*Functions!E6/1000,- O7),"N/A") -> -4
A5: Test requirement | C5: <Brief description about requirements which are tested in this function>
A6: Passed | C6: Failed | F6: Untested | L6: N/A/B | O6: Total Test Cases
A7: =COUNTIF(F70:HP70,"P") -> 11 | C7: =COUNTIF(F70:HP70,"F") -> 3 | F7: =SUM(O7,- A7,- C7) -> 0 | L7: =COUNTIF(E69:HP69,"N") -> 10 | M7: =COUNTIF(E69:HP69,"A") -> 3 | N7: =COUNTIF(E69:HP69,"B") -> 1 | O7: =COUNTA(E9:HS9) -> 14
F9: UTCID01 | G9: UTCID02 | H9: UTCID03 | I9: UTCID04 | J9: UTCID05 | K9: UTCID06 | L9: UTCID07 | M9: UTCID08 | N9: UTCID09 | O9: UTCID10 | P9: UTCID11 | Q9: UTCID12 | R9: UTCID13 | S9: UTCID14
A10: Condition | B10: Precondition
D11: Can connect with server
D12: API endpoint up, DB reachable
B13: fullName
D14: Lê Nguyên An | F14: O | I14: O | J14: O | K14: O | L14: O | M14: O | N14: O | O14: O | P14: O | Q14: O | R14: O | S14: O
D15: "" (Emplty string) | G15: O
D16: 31 | H16: O
B17: email
D18: ww@w.w | F18: O | G18: O | H18: O | J18: O | K18: O | L18: O | M18: O | N18: O | O18: O | P18: O | Q18: O | R18: O | S18: O
D19: 3 | I19: O
B20: phone
D21: 902846869 | F21: O | G21: O | H21: O | I21: O | K21: O | L21: O | M21: O | N21: O | O21: O | P21: O | Q21: O | R21: O | S21: O
D22: 2009 | J22: O
B23: address
D24: 15/39 Tran Binh Trong | F24: O | G24: O | H24: O | I24: O | J24: O | L24: O | M24: O | N24: O | O24: O | P24: O | Q24: O | R24: O | S24: O
D25: "" (Emplty string) | K25: O
B26: wardCode
D27: 3026 | F27: O | G27: O | H27: O | I27: O | J27: O | K27: O | M27: O | N27: O | O27: O | P27: O | Q27: O | R27: O | S27: O
D28: XYZ | L28: O
B29: districtId
D30: 1425 | F30: O | G30: O | H30: O | I30: O | J30: O | K30: O | L30: O | N30: O | O30: O | P30: O | Q30: O | R30: O | S30: O
D31: aBC | M31: O
B32: cityId
D33: 1489 | F33: O | G33: O | H33: O | I33: O | J33: O | K33: O | L33: O | M33: O | O33: O | P33: O | Q33: O | R33: O | S33: O
D34: X15X | N34: O
B35: businessType
D36: Family | F36: O | G36: O | H36: O | I36: O | J36: O | K36: O | L36: O | M36: O | N36: O | P36: O | Q36: O | R36: O | S36: O
D37: no choose | O37: O
B38: taxCode
B39: taxCode | D39: 11041731 | F39: O | G39: O | H39: O | I39: O | J39: O | K39: O | L39: O | M39: O | N39: O | O39: O | Q39: O | R39: O | S39: O
D40: BSDA | P40: O
B41: brandName
D42: Hoa Hai | F42: O | G42: O | H42: O | I42: O | J42: O | K42: O | L42: O | M42: O | N42: O | O42: O | P42: O | R42: O | S42: O
...

Sheet createWalletOrderPayment
A2: Function Code | F2: Function Name | L2: =Functions!D12 -> createWalletOrderPayment
A3: Created By | C3: An | F3: Executed By | L3: An
A4: Lines of code | F4: Lack of test cases | L4: =IF(Functions!E6<>"N/A",SUM(C4*Functions!E6/1000,- O8),"N/A") -> -7
A6: Test requirement
A7: Passed | C7: Failed | F7: Untested | L7: N/A/B | O7: Total Test Cases
A8: =COUNTIF(F51:HI51,"P") -> 7 | C8: =COUNTIF(F51:HI51,"F") -> 0 | F8: =SUM(O8,- A8,- C8) -> 0 | L8: =COUNTIF(E50:HI50,"N") -> 5 | M8: =COUNTIF(E50:HI50,"A") -> 1 | N8: =COUNTIF(E50:HI50,"B") -> 1 | O8: =COUNTA(E10:HL10) -> 7
F10: UTCID01 | G10: UTCID02 | H10: UTCID03 | I10: UTCID04 | J10: UTCID05 | K10: UTCID06 | L10: UTCID07
A11: Condition | B11: Precondition
D12: Can connect with server
D13: The user is authenticated and authorized
D14: The provided email is valid and registered
D15: There is no network timeout or server-side crash
B17: servicePackId
D18: 1 | F18: O | H18: O | I18: O | J18: O | K18: O | L18: O
D19: Ac | G19: O
B20: orderDepositId
D21: 1 | F21: O | G21: O | I21: O | J21: O | K21: O | L21: O
D22: null | H22: O
B23: transactionType
D24: DEPOSIT | F24: O | G24: O | H24: O | J24: O | K24: O | L24: O
D25: Null | I25: O
B26: email
D27: ww@w.w | F27: O | G27: O | H27: O | I27: O | K27: O
D28: null | L28: O
D29: anle.com | J29: O
B30: returnUrl
D31: App / Web link url | F31: O | G31: O | H31: O | I31: O | J31: O | L31: O
D32: htt!://@wood... | K32: O
A33: Confirm | B33: Return
D34: payment response | F34: O | G34: O | H34: O | I34: O | J34: O | K34: O | L34: O
B35: Exception
D36: MissingServicePackId | G36: O
D37: MissingEmail | L37: O
D38: InvalidReturnUrl | K38: O
D39: MissingTransaction
D40: InvalidEmail | J40: O
B41: Log message
D42: email format is invalid | J42: O
D43: email is required | L43: O
D44: orderDepositId is required | H44: O
...

Sheet createUserAddress
A2: Function Code | C2: =Functions!E13 -> 0 | F2: Function Name | L2: =Functions!D13 -> createUserAddress
A3: Created By | C3: <Developer Name> | F3: Executed By
A4: Lines of code | C4: 300 | F4: Lack of test cases | L4: =IF(Functions!E6<>"N/A",SUM(C4*Functions!E6/1000,- O7),"N/A") -> 24
A5: Test requirement | C5: <Brief description about requirements which are tested in this function>
A6: Passed | C6: Failed | F6: Untested | L6: N/A/B | O6: Total Test Cases
A7: =COUNTIF(F50:HH50,"P") -> 5 | C7: =COUNTIF(F50:HH50,"F") -> 1 | F7: =SUM(O7,- A7,- C7) -> 0 | L7: =COUNTIF(E49:HH49,"N") -> 5 | M7: =COUNTIF(E49:HH49,"A") -> 0 | N7: =COUNTIF(E49:HH49,"B") -> 1 | O7: =COUNTA(E9:HK9) -> 6
F9: UTCID01 | G9: UTCID02 | H9: UTCID03 | I9: UTCID04 | J9: UTCID05 | K9: UTCID06
A10: Condition | B10: Precondition
D11: Can connect with server
B14: isDefault
D15: "true" | F15: O | G15: O | H15: O | I15: O | J15: O | K15: O
B16: address
D17: "15/39 Tran Binh Trong" | F17: O | H17: O | I17: O | J17: O | K17: O
D18: "null" | G18: O
B19: wardCode
D20: 70312 | F20: O | G20: O | I20: O | J20: O | K20: O
D21: asdc | H21: O
B22: districtId
D23: 1989 | F23: O | G23: O | H23: O | J23: O | K23: O
D24: a | I24: O
B25: cityId
D26: 264 | F26: O | G26: O | H26: O | I26: O | K26: O
D27: "" | J27: O
B28: userId
D29: 1 | F29: O | G29: O | H29: O | I29: O | J29: O
D30: 0 | K30: O
A31: Confirm | B31: Return
D32: 1 | F32: O
D33: 2 | G33: O | H33: O | I33: O | J33: O | K33: O
B34: Exception
D35: InvalidUserId | K35: O
D36: MissingAddress | G36: O
D37: MissingCityId | J37: O
D38: MissingDistrictId
D39: InvalidWardCode | H39: O
D40: InvaliddistrictId | I40: O
B41: Log message
D42: "success" | F42: O
D43: userId must be > 0 | K43: O
D44: address is required | G44: O
...

Sheet signup
A2: Function Code | C2: =Functions!E11 -> 0 | F2: Function Name | L2: =Functions!D14 -> signup
A3: Created By | C3: <Developer Name> | F3: Executed By
A4: Lines of code | C4: 100 | F4: Lack of test cases | L4: =IF(Functions!E6<>"N/A",SUM(C4*Functions!E6/1000,- O7),"N/A") -> -5
A5: Test requirement | C5: <Brief description about requirements which are tested in this function>
A6: Passed | C6: Failed | F6: Untested | L6: N/A/B | O6: Total Test Cases
A7: =COUNTIF(F36:HQ36,"P") -> 12 | C7: =COUNTIF(F36:HQ36,"F") -> 2 | F7: =SUM(O7,- A7,- C7) -> 1 | L7: =COUNTIF(E35:HQ35,"N") -> 11 | M7: =COUNTIF(E35:HQ35,"A") -> 3 | N7: =COUNTIF(E35:HQ35,"B") -> 1 | O7: =COUNTA(E9:HT9) -> 15
F9: UTCID01 | G9: UTCID02 | H9: UTCID03 | I9: UTCID04 | J9: UTCID05 | K9: UTCID06 | L9: UTCID07 | M9: UTCID08 | N9: UTCID09 | O9: UTCID10 | P9: UTCID11 | Q9: UTCID12 | R9: UTCID13 | S9: UTCID14 | T9: UTCID15
A10: Condition | B10: Precondition
D11: Can connect with server
B12: API endpoint up, DB reachable
B14: fullName
B15: "Nguyen Van A" | F15: O
B16: "" (Empty string) | G16: O
B17: email
B18: abc@domain.com | F18: O
B19: "" (Empty string) | G19: O
B20: invalid_email
B21: password | F21: O
B22: "abc124@" | G22: O
B23: "" (Empty string) | G23: O
B24: confirmPass
B25: matches password | F25: O
B26: not matching | G26: O
B27: Return | F27: O | G27: O
D28: CoreApiResponse
B30: Exception
B32: Log message
D33: "Email không hợp lệ"
B34: "Tài khoản đã được đăng ký thành công!"
A35: Result | D35: "input1 is null" | F35: A | G35: N | H35: N | I35: N | J35: N | K35: B | L35: A | M35: N | N35: N | O35: N | P35: N | Q35: N | R35: A | S35: N | T35: N
B36: Type(N : Normal, A : Abnormal, B : Boundary) | F36: P | G36: P | H36: P | I36: P | J36: P | K36: F | L36: F | M36: P | N36: P | O36: P | P36: P | Q36: P | S36: P | T36: P
B37: Passed/Failed | F37: 39139 | G37: 39139 | H37: 39140 | I37: 39141 | J37: 39142 | K37: 39143 | L37: 39144 | M37: 39145 | N37: 39146 | O37: 39147 | P37: 39148 | Q37: 39149 | R37: 39150 | S37: 39151 | T37: 39152
B38: Executed Date | K38: DFID002 | L38: DFID004 | M38: DFID005 | N38: DFID006 | O38: DFID007 | P38: DFID008 | Q38: DFID009 | R38: DFID010 | S38: DFID011 | T38: DFID012
B39: Defect ID

Sheet saveQuotationDetails
A2: Function Code | C2: =Functions!E11 -> 0 | F2: Function Name | L2: =Functions!D15 -> saveQuotationDetails
A3: Created By | C3: <Developer Name> | F3: Executed By
A4: Lines of code | C4: 100 | F4: Lack of test cases | L4: =IF(Functions!E6<>"N/A",SUM(C4*Functions!E6/1000,- O7),"N/A") -> -5
A5: Test requirement | C5: <Brief description about requirements which are tested in this function>
A6: Passed | C6: Failed | F6: Untested | L6: N/A/B | O6: Total Test Cases
A7: =COUNTIF(F32:HQ32,"P") -> 11 | C7: =COUNTIF(F32:HQ32,"F") -> 3 | F7: =SUM(O7,- A7,- C7) -> 1 | L7: =COUNTIF(E31:HQ31,"N") -> 11 | M7: =COUNTIF(E31:HQ31,"A") -> 3 | N7: =COUNTIF(E31:HQ31,"B") -> 1 | O7: =COUNTA(E9:HT9) -> 15
F9: UTCID01 | G9: UTCID02 | H9: UTCID03 | I9: UTCID04 | J9: UTCID05 | K9: UTCID06 | L9: UTCID07 | M9: UTCID08 | N9: UTCID09 | O9: UTCID10 | P9: UTCID11 | Q9: UTCID12 | R9: UTCID13 | S9: UTCID14 | T9: UTCID15
A10: Condition | B10: Precondition
D11: Can connect with server
B14: requestedProductId
B15: Valid ID | F15: O
B16: Invalid ID | G16: O
B18: quotations
B19: Empty list | H19: O
B20: Multiple valid entries | F20: O
A23: Confirm | B23: Return
D24: T
D25: F
B26: Exception
B27: "RequestedProduct not found" | G27: O
B28: Log message
A31: Result | B31: Type(N : Normal, A : Abnormal, B : Boundary) | F31: A | G31: N | H31: N | I31: N | J31: N | K31: B | L31: A | M31: N | N31: N | O31: N | P31: N | Q31: N | R31: A | S31: N | T31: N
B32: Passed/Failed | F32: P | G32: P | H32: F | I32: P | J32: P | K32: F | L32: F | M32: P | N32: P | O32: P | P32: P | Q32: P | S32: P | T32: P
B33: Executed Date | F33: 45935 | G33: 45935 | H33: 45935 | I33: 45935 | J33: 39142 | K33: 39143 | L33: 39144 | M33: 39145 | N33: 39146 | O33: 39147 | P33: 39148 | Q33: 39149 | R33: 39150 | S33: 39151 | T33: 39152
B34: Defect ID | F34: D024 | G34: D025 | H34: D026 | K34: DFID002 | L34: DFID004 | M34: DFID005 | N34: DFID006 | O34: DFID007 | P34: DFID008 | Q34: DFID009 | R34: DFID010 | S34: DFID011 | T34: DFID012

Sheet saveGuaranteeQuotationDetails
A2: Function Code | C2: =Functions!E11 -> 0 | F2: Function Name | L2: =Functions!D16 -> saveGuaranteeQuotationDetails
A3: Created By | C3: <Developer Name> | F3: Executed By
A4: Lines of code | C4: 100 | F4: Lack of test cases | L4: =IF(Functions!E6<>"N/A",SUM(C4*Functions!E6/1000,- O7),"N/A") -> -5
A5: Test requirement | C5: <Brief description about requirements which are tested in this function>
A6: Passed | C6: Failed | F6: Untested | L6: N/A/B | O6: Total Test Cases
A7: =COUNTIF(F30:HQ30,"P") -> 12 | C7: =COUNTIF(F30:HQ30,"F") -> 2 | F7: =SUM(O7,- A7,- C7) -> 1 | L7: =COUNTIF(E29:HQ29,"N") -> 11 | M7: =COUNTIF(E29:HQ29,"A") -> 3 | N7: =COUNTIF(E29:HQ29,"B") -> 1 | O7: =COUNTA(E9:HT9) -> 15
F9: UTCID01 | G9: UTCID02 | H9: UTCID03 | I9: UTCID04 | J9: UTCID05 | K9: UTCID06 | L9: UTCID07 | M9: UTCID08 | N9: UTCID09 | O9: UTCID10 | P9: UTCID11 | Q9: UTCID12 | R9: UTCID13 | S9: UTCID14 | T9: UTCID15
A10: Condition | B10: Precondition
D11: Can connect with server
B14: guaranteeOrderId
D15: Valid ID | F15: O
D16: Invalid ID | G16: O
D17: 31
B18: quotations
B19: Multiple valid items | F19: O
A21: Confirm | B21: Return
D22: T | F22: O | G22: O
D23: F
B24: Exception
B26: Log message
D27: "success"
D28: "input1 is null"
A29: Result | B29: Type(N : Normal, A : Abnormal, B : Boundary) | F29: A | G29: N | H29: N | I29: N | J29: N | K29: B | L29: A | M29: N | N29: N | O29: N | P29: N | Q29: N | R29: A | S29: N | T29: N
B30: Passed/Failed | F30: P | G30: P | H30: P | I30: P | J30: P | K30: F | L30: F | M30: P | N30: P | O30: P | P30: P | Q30: P | S30: P | T30: P
B31: Executed Date | F31: 45935 | G31: 45935 | H31: 45935 | I31: 45935 | J31: 39142 | K31: 39143 | L31: 39144 | M31: 39145 | N31: 39146 | O31: 39147 | P31: 39148 | Q31: 39149 | R31: 39150 | S31: 39151 | T31: 39152
B32: Defect ID | K32: DFID002 | L32: DFID004 | M32: DFID005 | N32: DFID006 | O32: DFID007 | P32: DFID008 | Q32: DFID009 | R32: DFID010 | S32: DFID011 | T32: DFID012

Sheet createPost
A2: Function Code | F2: Function Name | L2: =Functions!D17 -> createPost
A3: Created By | C3: Phúc | F3: Executed By | L3: Phúc
A4: Lines of code | F4: Lack of test cases | L4: 0
A5: Test requirement
A6: Passed | C6: Failed | F6: Untested | L6: N/A/B | O6: Total Test Cases
A7: =COUNTIF(F44:HQ44,"P") -> 8 | C7: =COUNTIF(F44:HQ44,"F") -> 0 | F7: =SUM(O7,- A7,- C7) -> 0 | L7: =COUNTIF(E43:HQ43,"N") -> 2 | M7: =COUNTIF(E43:HQ43,"A") -> 5 | N7: =COUNTIF(E43:HQ43,"B") -> 1 | O7: =COUNTA(E9:HT9) -> 8
F9: UTCID01 | G9: UTCID02 | H9: UTCID03 | I9: UTCID04 | J9: UTCID05 | K9: UTCID06 | L9: UTCID07 | M9: UTCID08
A10: Condition | B10: Precondition
C11: Can connect with server
B14: title
C15: "Woodworker Post" | F15: O | I15: O | J15: O | K15: O | L15: O | M15: O
C16: "" | G16: O
C17: "A".repeat(255) // 255 characters | H17: O
B18: description
B19: "This is a description of the woodworker's post." | F19: O | G19: O | H19: O | K19: O | L19: O | M19: O
D20: "" | I20: O
B21: "D".repeat(1000) | J21: O
B22: imgUrls
D23: "https://imgur.com/aBc123.png" | F23: O | G23: O | H23: O | I23: O | J23: O | M23: O
D24: "" | K24: O
B25: "https://123.com/123.123" | L25: O
B26: woodworkerId
D27: 1 | F27: O | G27: O | H27: O | I27: O | J27: O | K27: O | L27: O
D28: -1 | M28: O
A29: Confirm | B29: Return
D30: PostDetailRes | F30: O | H30: O
B32: Exception
B34: Log message
B35: "Post created with title: 'Woodworker Post'" | F35: O
B36: "Title is empty, validation failed" | G36: O
B37: "Post created with title: 'A'.repeat(255)" | H37: O
B38: "Description is empty, validation failed" | I38: O
B39: "Description exceeds maximum length" | J39: O
B40: "No image URL provided" | K40: O
B41: "Invalid image URL provided" | L41: O
B42: "Woodworker ID cannot be negative" | M42: O
A43: Result | B43: Type(N : Normal, A : Abnormal, B : Boundary) | F43: N | G43: A | H43: N | I43: A | J43: B | K43: A | L43: A | M43: A
B44: Passed/Failed | F44: P | G44: P | H44: P | I44: P | J44: P | K44: P | L44: P | M44: P
B45: Executed Date | F45: 45781 | G45: 45781 | H45: 45781 | I45: 45781 | J45: 45781 | K45: 45781 | L45: 45781 | M45: 45781
B46: Defect ID

Sheet createContractCustomize
A2: Function Code | C2: =Functions!E11 -> 0 | F2: Function Name | L2: =Functions!D18 -> createContractCustomize
A3: Created By | C3: <Developer Name> | F3: Executed By
A4: Lines of code | C4: 100 | F4: Lack of test cases | L4: =IF(Functions!E6<>"N/A",SUM(C4*Functions!E6/1000,- O7),"N/A") -> -5
A5: Test requirement | C5: <Brief description about requirements which are tested in this function>
A6: Passed | C6: Failed | F6: Untested | L6: N/A/B | O6: Total Test Cases
A7: =COUNTIF(F40:HQ40,"P") -> 12 | C7: =COUNTIF(F40:HQ40,"F") -> 2 | F7: =SUM(O7,- A7,- C7) -> 1 | L7: =COUNTIF(E39:HQ39,"N") -> 11 | M7: =COUNTIF(E39:HQ39,"A") -> 3 | N7: =COUNTIF(E39:HQ39,"B") -> 1 | O7: =COUNTA(E9:HT9) -> 15
F9: UTCID01 | G9: UTCID02 | H9: UTCID03 | I9: UTCID04 | J9: UTCID05 | K9: UTCID06 | L9: UTCID07 | M9: UTCID08 | N9: UTCID09 | O9: UTCID10 | P9: UTCID11 | Q9: UTCID12 | R9: UTCID13 | S9: UTCID14 | T9: UTCID15
A10: Condition | B10: Precondition
D11: Can connect with server
B14: Date
D15: 29 | F15: O | G15: O
D16: 30
D17: 31
B18: Month
D19: 2 | F19: O
D20: 3 | G20: O
D21: 4
B22: Year
D23: 2000 | F23: O
D24: 2009 | G24: O
A31: Confirm | B31: Return
D32: T | F32: O | G32: O
D33: F
B34: Exception
B36: Log message
D37: "success"
D38: "input1 is null"
A39: Result | B39: Type(N : Normal, A : Abnormal, B : Boundary) | F39: A | G39: N | H39: N | I39: N | J39: N | K39: B | L39: A | M39: N | N39: N | O39: N | P39: N | Q39: N | R39: A | S39: N | T39: N
B40: Passed/Failed | F40: P | G40: P | H40: P | I40: P | J40: P | K40: F | L40: F | M40: P | N40: P | O40: P | P40: P | Q40: P | S40: P | T40: P
B41: Executed Date | F41: 39139 | G41: 39139 | H41: 39140 | I41: 39141 | J41: 39142 | K41: 39143 | L41: 39144 | M41: 39145 | N41: 39146 | O41: 39147 | P41: 39148 | Q41: 39149 | R41: 39150 | S41: 39151 | T41: 39152
B42: Defect ID | K42: DFID002 | L42: DFID004 | M42: DFID005 | N42: DFID006 | O42: DFID007 | P42: DFID008 | Q42: DFID009 | R42: DFID010 | S42: DFID011 | T42: DFID012

Sheet createReview
A2: Function Code | C2: =Functions!E11 -> 0 | F2: Function Name | L2: =Functions!D19 -> createReview
A3: Created By | C3: <Developer Name> | F3: Executed By
A4: Lines of code | C4: 100 | F4: Lack of test cases | L4: =IF(Functions!E6<>"N/A",SUM(C4*Functions!E6/1000,- O7),"N/A") -> -5
A5: Test requirement | C5: <Brief description about requirements which are tested in this function>
A6: Passed | C6: Failed | F6: Untested | L6: N/A/B | O6: Total Test Cases
A7: =COUNTIF(F40:HQ40,"P") -> 12 | C7: =COUNTIF(F40:HQ40,"F") -> 2 | F7: =SUM(O7,- A7,- C7) -> 1 | L7: =COUNTIF(E39:HQ39,"N") -> 11 | M7: =COUNTIF(E39:HQ39,"A") -> 3 | N7: =COUNTIF(E39:HQ39,"B") -> 1 | O7: =COUNTA(E9:HT9) -> 15
F9: UTCID01 | G9: UTCID02 | H9: UTCID03 | I9: UTCID04 | J9: UTCID05 | K9: UTCID06 | L9: UTCID07 | M9: UTCID08 | N9: UTCID09 | O9: UTCID10 | P9: UTCID11 | Q9: UTCID12 | R9: UTCID13 | S9: UTCID14 | T9: UTCID15
A10: Condition | B10: Precondition
D11: Can connect with server
B14: Date
D15: 29 | F15: O | G15: O
D16: 30
D17: 31
B18: Month
D19: 2 | F19: O
D20: 3 | G20: O
D21: 4
B22: Year
D23: 2000 | F23: O
D24: 2009 | G24: O
A31: Confirm | B31: Return
D32: T | F32: O | G32: O
D33: F
B34: Exception
B36: Log message
D37: "success"
D38: "input1 is null"
A39: Result | B39: Type(N : Normal, A : Abnormal, B : Boundary) | F39: A | G39: N | H39: N | I39: N | J39: N | K39: B | L39: A | M39: N | N39: N | O39: N | P39: N | Q39: N | R39: A | S39: N | T39: N
B40: Passed/Failed | F40: P | G40: P | H40: P | I40: P | J40: P | K40: F | L40: F | M40: P | N40: P | O40: P | P40: P | Q40: P | S40: P | T40: P
B41: Executed Date | F41: 39139 | G41: 39139 | H41: 39140 | I41: 39141 | J41: 39142 | K41: 39143 | L41: 39144 | M41: 39145 | N41: 39146 | O41: 39147 | P41: 39148 | Q41: 39149 | R41: 39150 | S41: 39151 | T41: 39152
B42: Defect ID | K42: DFID002 | L42: DFID004 | M42: DFID005 | N42: DFID006 | O42: DFID007 | P42: DFID008 | Q42: DFID009 | R42: DFID010 | S42: DFID011 | T42: DFID012

Sheet addDesignIdea
A2: Function Code | F2: Function Name | L2: =Functions!D20 -> addDesignIdea
A3: Created By | C3: Luân | F3: Executed By | L3: Luân
A4: Lines of code | F4: Lack of test cases | L4: 0
A5: Test requirement | C5: Verify that createProduct enforces woodworkerId ≥ 0 & exists, categoryId > 0 & exists, at least one configuration with values, and price > 0 — returning a valid ProductResponse on success or throwing AppException with the right message on failure.
A6: Passed | C6: Failed | F6: Untested | L6: N/A/B | O6: Total Test Cases
A7: =COUNTIF(F50:HJ50,"P") -> 8 | C7: =COUNTIF(F50:HJ50,"F") -> 0 | F7: =SUM(O7,- A7,- C7) -> 0 | L7: =COUNTIF(E49:HJ49,"N") -> 1 | M7: =COUNTIF(E49:HJ49,"A") -> 7 | N7: =COUNTIF(E49:HJ49,"B") -> 0 | O7: =COUNTA(E9:HM9) -> 8
F9: UTCID01 | G9: UTCID02 | H9: UTCID03 | I9: UTCID04 | J9: UTCID05 | K9: UTCID06 | L9: UTCID07 | M9: UTCID08
A10: Condition | B10: Precondition
D11: Can connect with server
D12: Logged as a woodworker account
B13: isInstall
D14: TRUE | G14: O | I14: O | J14: O | K14: O | L14: O | M14: O
D15: FALSE | H15: O
D16: null / emplty | F16: O
B17: woodworkerId
D18: 1 (valid) | F18: O | I18: O | J18: O | K18: O | L18: O | M18: O
D19: 0 (invalid id) | G19: O
D20: null / emplty | H20: O
B21: img
D22: valid img url link | F22: O | G22: O | H22: O | J22: O | K22: O | L22: O | M22: O
D23: null / emplty | I23: O
B24: description
D25: null / emplty | J25: O
D26: description | F26: O | G26: O | H26: O | I26: O | K26: O | L26: O
B27: categoryId
D28: 1 (valid id) | F28: O | G28: O | H28: O | I28: O | J28: O | L28: O | M28: O
D29: 0 (invalid id) | K29: O
B30: configurations
D31: [ { "id": 0, "name": "string", "values": [ { "id": 0, "name": "string" } ] } ] | L31: O
D32: [ { "id": 1, "name": "Config1", "values": [ { "id": 1, "name": "Value1" } ] } ] | F32: O | G32: O | H32: O | I32: O | J32: O | K32: O | M32: O
B33: prices
D34: [ { "config": [ 0 ], "configValue": [ 0 ], "price": 0 } ] | L34: O
D35: [ { "config": [ 1 ], "configValue": [ 1 ], "price": 1000000 } ] | F35: O | G35: O | H35: O | I35: O | J35: O | K35: O | M35: O
A36: Confirm | B36: Return
D37: CoreApiResponse | F37: O | G37: O | H37: O | I37: O | J37: O | K37: O | L37: O | M37: O
B38: Exception
B40: Log message
D41: "Must provide data to isInstall" | F41: O
D42: "Cannot find woodworker" | G42: O
D43: "Must provide data to woodworkerId" | H43: O
...

Sheet createPersonalOrder
A2: Function Code | F2: Function Name | L2: =Functions!D21 -> createPersonalOrder
A3: Created By | C3: Luân | F3: Executed By | L3: Luân
A4: Lines of code | F4: Lack of test cases | L4: 0
A5: Test requirement
A6: Passed | C6: Failed | F6: Untested | L6: N/A/B | O6: Total Test Cases
A7: =COUNTIF(F60:HL60,"P") -> 8 | C7: =COUNTIF(F60:HL60,"F") -> 2 | F7: =SUM(O7,- A7,- C7) -> 0 | L7: =COUNTIF(E59:HL59,"N") -> 1 | M7: =COUNTIF(E59:HL59,"A") -> 9 | N7: =COUNTIF(E59:HL59,"B") -> 0 | O7: =COUNTA(E9:HO9) -> 10
F9: UTCID01 | G9: UTCID02 | H9: UTCID03 | I9: UTCID04 | J9: UTCID05 | K9: UTCID06 | L9: UTCID07 | M9: UTCID08 | N9: UTCID09 | O9: UTCID10
A10: Condition | B10: Precondition
D11: Can connect with server
B12: availableServiceId
D13: 1 (valid id) | G13: O | H13: O | I13: O | J13: O | K13: O | L13: O | M13: O | N13: O | O13: O
D14: 0 (invalid id) | F14: O
B15: toDistrictId
D16: 1 (valid id) | F16: O | H16: O | I16: O | J16: O | K16: O | L16: O | M16: O | N16: O | O16: O
D17: 0 (invalid id) | G17: O
B18: toWardCode
D19: "3030" (valid code) | F19: O | G19: O | I19: O | J19: O | K19: O | L19: O | M19: O | N19: O | O19: O
D20: "0" (invalid code) | H20: O
B21: ghnServiceId
D22: 1 (valid id) | F22: O | G22: O | H22: O | I22: O | J22: O | K22: O | L22: O | M22: O | N22: O | O22: O
B23: ghnServiceTypeId
D24: 1 (valid id) | F24: O | G24: O | H24: O | I24: O | J24: O | K24: O | L24: O | M24: O | N24: O | O24: O
B25: note
D26: null / empty string | I26: O
D27: "Note" | F27: O | G27: O | H27: O | J27: O | K27: O | L27: O | M27: O | N27: O | O27: O
B28: userId
D29: 1 (valid id) | F29: O | G29: O | H29: O | J29: O | K29: O | L29: O | M29: O | N29: O | O29: O
D30: 0 (invalid id) | I30: O
B31: address
D32: "123 street" | F32: O | G32: O | H32: O | I32: O | K32: O | L32: O | M32: O | N32: O | O32: O
D33: null / empty string | J33: O
B34: requestedProducts
D35: [ { "categoryId": "string", "quantity": "string", "techSpecs": [ { "techSpecId": 0, "values": "string" } ] } ] | K35: O
D36: [ { "categoryId": "1", "quantity": "1", "techSpecs": [ { "techSpecId": 1, "values": "1" } ] } ] | F36: O | G36: O | H36: O | I36: O | J36: O | L36: O | M36: O | N36: O | O36: O
B37: isInstall
D38: TRUE | F38: O | G38: O | H38: O | I38: O | J38: O | K38: O | M38: O | O38: O
D39: FALSE | N39: O
D40: null / empty string | L40: O
B41: priceShipping
D42: null / empty string | N42: O
...

Sheet createCustomizeOrder
A2: Function Code | F2: Function Name | L2: =Functions!D22 -> createCustomizeOrder
A3: Created By | C3: Luân | F3: Executed By | L3: Luân
A4: Lines of code | F4: Lack of test cases | L4: 0
A5: Test requirement
A6: Passed | C6: Failed | F6: Untested | L6: N/A/B | O6: Total Test Cases
A7: =COUNTIF(F60:HL60,"P") -> 9 | C7: =COUNTIF(F60:HL60,"F") -> 1 | F7: =SUM(O7,- A7,- C7) -> 0 | L7: =COUNTIF(E59:HL59,"N") -> 1 | M7: =COUNTIF(E59:HL59,"A") -> 9 | N7: =COUNTIF(E59:HL59,"B") -> 0 | O7: =COUNTA(E9:HO9) -> 10
F9: UTCID01 | G9: UTCID02 | H9: UTCID03 | I9: UTCID04 | J9: UTCID05 | K9: UTCID06 | L9: UTCID07 | M9: UTCID08 | N9: UTCID09 | O9: UTCID10
A10: Condition | B10: Precondition
D11: Can connect with server
B12: availableServiceId
D13: 1 (valid id) | G13: O | H13: O | I13: O | J13: O | K13: O | L13: O | M13: O | N13: O | O13: O
D14: 0 (invalid id) | F14: O
B15: toDistrictId
D16: 1 (valid id) | F16: O | H16: O | I16: O | J16: O | K16: O | L16: O | M16: O | N16: O | O16: O
D17: 0 (invalid id) | G17: O
B18: toWardCode
D19: "3030" (valid code) | F19: O | G19: O | I19: O | J19: O | K19: O | L19: O | M19: O | N19: O | O19: O
D20: "0" (invalid code) | H20: O
B21: ghnServiceId
D22: 1 (valid id) | F22: O | G22: O | H22: O | I22: O | J22: O | K22: O | L22: O | M22: O | N22: O | O22: O
B23: ghnServiceTypeId
D24: 1 (valid id) | F24: O | G24: O | H24: O | I24: O | J24: O | K24: O | L24: O | M24: O | N24: O | O24: O
B25: description
D26: null / empty string | I26: O
D27: "Description" | F27: O | G27: O | H27: O | J27: O | K27: O | L27: O | M27: O | N27: O | O27: O
B28: userId
D29: 1 (valid id) | F29: O | G29: O | H29: O | J29: O | K29: O | L29: O | M29: O | N29: O | O29: O
D30: 0 (invalid id) | I30: O
B31: address
D32: "123 street" | F32: O | G32: O | H32: O | I32: O | K32: O | L32: O | M32: O | N32: O | O32: O
D33: null / empty string | J33: O
B34: designIdeaVariantIds
D35: [ { "designIdeaVariantId": 0, "quantity": 0 } ] | K35: O
D36: [ { "designIdeaVariantId": 1, "quantity": 1 } ] | F36: O | G36: O | H36: O | I36: O | J36: O | L36: O | M36: O | N36: O | O36: O
B37: isInstall
D38: TRUE | F38: O | G38: O | H38: O | I38: O | J38: O | K38: O | M38: O | O38: O
D39: FALSE | N39: O
D40: null / empty string | L40: O
B41: priceShipping
D42: null / empty string | N42: O
...
